{
 "cells": [
  {
   "cell_type": "code",
   "execution_count": 7,
   "metadata": {},
   "outputs": [],
   "source": [
    "import numpy as np\n",
    "import os\n",
    "import pandas as pd\n",
    "import sqlalchemy\n",
    "from sqlalchemy.ext.automap import automap_base\n",
    "from sqlalchemy.orm import Session\n",
    "from sqlalchemy import create_engine\n",
    "\n",
    "from flask import Flask, jsonify"
   ]
  },
  {
   "cell_type": "code",
   "execution_count": 8,
   "metadata": {},
   "outputs": [],
   "source": [
    "engine = create_engine(\"postgres://postgres:123abc@localhost:5432/project_2\")"
   ]
  },
  {
   "cell_type": "code",
   "execution_count": 9,
   "metadata": {},
   "outputs": [],
   "source": [
    "Base = automap_base()\n",
    "Base.prepare(engine, reflect=True)"
   ]
  },
  {
   "cell_type": "code",
   "execution_count": 13,
   "metadata": {},
   "outputs": [
    {
     "name": "stderr",
     "output_type": "stream",
     "text": [
      "ERROR:root:Internal Python error in the inspect module.\n",
      "Below is the traceback from this internal error.\n",
      "\n"
     ]
    },
    {
     "name": "stdout",
     "output_type": "stream",
     "text": [
      "Traceback (most recent call last):\n",
      "  File \"/Users/solicia/anaconda3/lib/python3.7/site-packages/IPython/core/interactiveshell.py\", line 3331, in run_code\n",
      "    exec(code_obj, self.user_global_ns, self.user_ns)\n",
      "  File \"<ipython-input-13-a2d93672eab4>\", line 1, in <module>\n",
      "    df=pd.read_csv('static/ArrivalCleaned.csv')\n",
      "  File \"/Users/solicia/anaconda3/lib/python3.7/site-packages/pandas/io/parsers.py\", line 676, in parser_f\n",
      "    return _read(filepath_or_buffer, kwds)\n",
      "  File \"/Users/solicia/anaconda3/lib/python3.7/site-packages/pandas/io/parsers.py\", line 448, in _read\n",
      "    parser = TextFileReader(fp_or_buf, **kwds)\n",
      "  File \"/Users/solicia/anaconda3/lib/python3.7/site-packages/pandas/io/parsers.py\", line 880, in __init__\n",
      "    self._make_engine(self.engine)\n",
      "  File \"/Users/solicia/anaconda3/lib/python3.7/site-packages/pandas/io/parsers.py\", line 1114, in _make_engine\n",
      "    self._engine = CParserWrapper(self.f, **self.options)\n",
      "  File \"/Users/solicia/anaconda3/lib/python3.7/site-packages/pandas/io/parsers.py\", line 1891, in __init__\n",
      "    self._reader = parsers.TextReader(src, **kwds)\n",
      "  File \"pandas/_libs/parsers.pyx\", line 374, in pandas._libs.parsers.TextReader.__cinit__\n",
      "  File \"pandas/_libs/parsers.pyx\", line 677, in pandas._libs.parsers.TextReader._setup_parser_source\n",
      "OSError: Initializing from file failed\n",
      "\n",
      "During handling of the above exception, another exception occurred:\n",
      "\n",
      "Traceback (most recent call last):\n",
      "  File \"/Users/solicia/anaconda3/lib/python3.7/site-packages/IPython/core/interactiveshell.py\", line 2044, in showtraceback\n",
      "    stb = value._render_traceback_()\n",
      "AttributeError: 'OSError' object has no attribute '_render_traceback_'\n",
      "\n",
      "During handling of the above exception, another exception occurred:\n",
      "\n",
      "Traceback (most recent call last):\n",
      "  File \"/Users/solicia/anaconda3/lib/python3.7/site-packages/IPython/core/ultratb.py\", line 1151, in get_records\n",
      "    return _fixed_getinnerframes(etb, number_of_lines_of_context, tb_offset)\n",
      "  File \"/Users/solicia/anaconda3/lib/python3.7/site-packages/IPython/core/ultratb.py\", line 319, in wrapped\n",
      "    return f(*args, **kwargs)\n",
      "  File \"/Users/solicia/anaconda3/lib/python3.7/site-packages/IPython/core/ultratb.py\", line 353, in _fixed_getinnerframes\n",
      "    records = fix_frame_records_filenames(inspect.getinnerframes(etb, context))\n",
      "  File \"/Users/solicia/anaconda3/lib/python3.7/inspect.py\", line 1502, in getinnerframes\n",
      "    frameinfo = (tb.tb_frame,) + getframeinfo(tb, context)\n",
      "  File \"/Users/solicia/anaconda3/lib/python3.7/inspect.py\", line 1460, in getframeinfo\n",
      "    filename = getsourcefile(frame) or getfile(frame)\n",
      "  File \"/Users/solicia/anaconda3/lib/python3.7/inspect.py\", line 696, in getsourcefile\n",
      "    if getattr(getmodule(object, filename), '__loader__', None) is not None:\n",
      "  File \"/Users/solicia/anaconda3/lib/python3.7/inspect.py\", line 725, in getmodule\n",
      "    file = getabsfile(object, _filename)\n",
      "  File \"/Users/solicia/anaconda3/lib/python3.7/inspect.py\", line 709, in getabsfile\n",
      "    return os.path.normcase(os.path.abspath(_filename))\n",
      "  File \"/Users/solicia/anaconda3/lib/python3.7/posixpath.py\", line 383, in abspath\n",
      "    cwd = os.getcwd()\n",
      "PermissionError: [Errno 1] Operation not permitted\n"
     ]
    },
    {
     "ename": "OSError",
     "evalue": "Initializing from file failed",
     "output_type": "error",
     "traceback": [
      "\u001b[0;31m---------------------------------------------------------------------------\u001b[0m"
     ]
    }
   ],
   "source": [
    "df=pd.read_csv('static/ArrivalCleaned.csv')"
   ]
  },
  {
   "cell_type": "code",
   "execution_count": null,
   "metadata": {},
   "outputs": [],
   "source": []
  }
 ],
 "metadata": {
  "kernelspec": {
   "display_name": "Python 3",
   "language": "python",
   "name": "python3"
  },
  "language_info": {
   "codemirror_mode": {
    "name": "ipython",
    "version": 3
   },
   "file_extension": ".py",
   "mimetype": "text/x-python",
   "name": "python",
   "nbconvert_exporter": "python",
   "pygments_lexer": "ipython3",
   "version": "3.7.3"
  }
 },
 "nbformat": 4,
 "nbformat_minor": 4
}
